Workbook

Sheet Case Study
A1: Ridge Business Center
A3: Ridge Business Center is a warehouse/office property in Charlotte. The property includes a well-maintained building totalling 50,000 sq ft in leasable area.
A4: The property has been offered for sale by the current owner at asking price of $5 Million. As a Financial Analyst of XYZ Investors, you are expected to identify if the property will
A5: be a good acquisition for the company. An investment must generate a minimum of 15% IRR for XYZ Investors.
A6: Please build a financial model using the assumptions below to provide an answer to the Management. Required sheets have been provided.
A8: Investment Assumptions
A9: Acquisition Date | B9: 44197
A10: Holding Period | B10: 5 years | C10: * time for which the property is owned
A11: Sale Date | B11: last day of 60th month
A12: Terminal Cap Rate | B12: 0.075 | C12: * This rate is used to determine Sale Price by the following formula: Sale Price= 5th Year NOI/Terminal Cap Rate
A13: Cost of Sale | B13: 0.02 | C13: * 2% of Sale Earnings go to broker/lawyer
A15: Loan Assumptions
A16: Loan Start Date | B16: 44197
A17: Term of Loan | B17: 5 years
A18: LTV | B18: 0.75 | C18: * of Price
A19: Interest Rate | B19: 0.04
A20: Loan Fees | B20: 0.01
A21: Amortization Period | B21: 25 years | C21: * Calculate monthly loan payments, you will need an amortization schedule
A23: Rent Assumptions
A24: 1) Assume rents increase every year on first day of the calendar year
A25: 2) Rents shown are Annual rents on a per square feet basis. Convert them to monthly rents and actual $ as and when required.
A26: 3) NNN leases are triple net leases, tenant has to pay their proportionate share of CAM, taxes and insurance over and above the rent
A27: 4) Consider Suite 1006 as vacant for the entire duration of 5 years
A29: Rent Roll ( As of 31 July, 2020)
A30: Suite | B30: Leased Area | C30: Status | D30: Lease Start Date | E30: Lease End Date | F30: Annual Rent PSF | G30: Rent Increase Date | H30: Rent Increase | I30: Lease Type
B31: (sq. ft) | D31: (mm/dd/yy) | E31: (mm/dd/yy) | F31: (as of 31 July, 20) | G31: (mm/dd/yy) | H31: Annual (%)
A32: 1001 | B32: 10000 | C32: Occupied | D32: 43160 | E32: =EOMONTH(D32,120) -> 46843 | F32: 12.15 | G32: 44197 | H32: 0.03 | I32: NNN
A33: 1002 | B33: 10000 | C33: Occupied | D33: 43617 | E33: =EOMONTH(D33,120) -> 47299 | F33: 11.5 | G33: 44197 | H33: 0.03 | I33: NNN
A34: 1003 | B34: 15000 | C34: Occupied | D34: 43831 | E34: =EOMONTH(D34,120) -> 47514 | F34: 10.75 | G34: 44197 | H34: 0.03 | I34: NNN
A35: 1004 | B35: 5000 | C35: Occupied | D35: 43160 | E35: =EOMONTH(D35,120) -> 46843 | F35: 12 | G35: 44197 | H35: 0.05 | I35: NNN
A36: 1005 | B36: 10000 | C36: Occupied | D36: 43617 | E36: =EOMONTH(D36,120) -> 47299 | F36: 12 | G36: 44197 | H36: 0.05 | I36: NNN
A37: 1006 | B37: 6000 | C37: Vacant
A38: Total | B38: =SUM(B32:B37) -> 56000 | F38: =SUMPRODUCT(F32:F36,B32:B36)/B38 -> 10.316964
A42: Expense Assumptions
A43: 1) All expenses are paid by landlord
A44: 2) All expenses grow 2% annually
A46: Expense Assumptions
A47: Expense Type | B47: Annual Expense ($)
A48: CAM | B48: 25000
A49: Taxes | B49: 75000
...

Sheet Questions
A1: Test Questions
B2: Test Taker First Name: | D2: Tushar
B3: Test Taker Last Name: | D3: Jadhav
B4: Test Taker Email: | D4: tusharr1807@gmail.com
B5: Test Taker Phone Number: | D5: 9146918917
B7: Instructions:
B8: 1. Answer all the questions below
B9: 2. Once you finish make a simple DCF model and debt amortization schedule with the assumptions provided
A14: Qs 1. | B14: Please refer to the excel sheet for the case study – Ridge Business Center. Use functions of Excel wherever necessary, no macros should be used for the case study. Calculate Levered IRR on the investment using the data provided.
A15: Answer:
A18: Qs 2. | B18: Investor A & B both invested $100,000 in a private investment and were promised 10% IRR.
B19: - A received $15,000 in Year 1 and $5000 in Year 2
B20: - B received $10,000 in Year 1 and $10,000 in Year 2
B21: Both of them exited the investment at the end of 2nd year. Even though both got 10% IRR on their investments, what could be the possible reason for B’s unhappiness?
A22: Answer: | B22: Here, A has received more money back in year 1 as compared to B. A will have a better chance of re investing the received money as compared to B who has got less than A. A has better liquidity,less risk and can re invest a higher sum earlier.on the other hand, B has high risk due to delayed CF and A receiving more cash early.
A25: Qs 3. | B25: Bond yields are inversely related to Interest Rates. What is the explanation for this relationship?
A26: Answer: | B26: Bonds pay a fixed coupon whereas market rates keep changing over time. As bond coupons are fixed , if the market rate rises the bond value will fall behind as compared to the market rate. Therefore the price of existing bonds must fall so that the yield matches the high rate and vice versa.
A29: Qs 4. | B29: What is DSCR? Why is it important to lenders?
A30: Answer: | B30: DSCR is Debt Service Coverage Ratio which tells whether a project is earning enough to meet its loan obligations / pay them off. A healthy business will be in a comfortable position to meet its obligations as compared to a company generating less earnings/cash. For lenders it is important as it shows the risk in the company that they are going to lend the money to. If DSCR >1 , the company generates enough money to pay off the lenders, it also helps lenders to decide
B31: how much money can they lend and at what rate.
A34: Qs 5. | B34: Our client is a real estate private equity company that focuses on multifamily acquisitions. A property we are looking at has a net operating income (NOI) of $567,678. The asking price is $10,650,567.
B35: What is the cap rate?
A36: Answer: | B36: Cap rate is the ratio of a property's net operating income to its purchase price. It tells the return the property generates from operations, it measures the income return on a real estate asset. In the given example the cap rate will be 5.33%…which means if purchased the property will earn 5.34% per year before financing
A39: Qs 6. | B39: Describe what a promote structure is (also known as a waterfall) for sponsors and investors in real estate?
A40: Answer: | B40: A promote structure is a profit sharing system where investors get their capital and preferred return first, and only after meeting those hurdles the GP receives an enhanced share of profits. It rewards the sponsor with a higher carried interest only if the project outperforms, aligning both parties’ incentives.

Sheet Dashboard
A3: You must calculate the sections mentioned below on this page, you can add assumptions or other information you deem relevant to this dashboard page
A5: Purchase Price | C5: 5000000
A6: Net Sale Price | C6: ='Yearly Cashflow'!H8 -> 6468931.1
A7: Net Cash Flow Before Debt (yearly) | C7: =SUM('Monthly Cashflow'!E40:P40) -> 408682.5 | D7: =SUM('Monthly Cashflow'!Q40:AB40) -> 426622.97 | E7: =SUM('Monthly Cashflow'!AC40:AN40) -> 445328.66 | F7: =SUM('Monthly Cashflow'!AO40:AZ40) -> 464832.73 | G7: =SUM('Monthly Cashflow'!BA40:BL40) -> 485169.83
A8: Net Cash Flow After Debt (yearly) | C8: =SUM('Monthly Cashflow'!E46:'Monthly Cashflow'!P46) -> 171155.92 | D8: =SUM('Monthly Cashflow'!Q46:'Monthly Cashflow'!AB46) -> 189096.4 | E8: =SUM('Monthly Cashflow'!AC46:'Monthly Cashflow'!AN46) -> 207802.09 | F8: =SUM('Monthly Cashflow'!AO46:'Monthly Cashflow'!AZ46) -> 227306.16 | G8: =SUM('Monthly Cashflow'!BA46:'Monthly Cashflow'!BL46) -> 247643.26
A10: Sources and Uses of Cash Flow | E10: Returns & Yields
A11: Sources | B11: Total | C11: % | E11: Equity Multiple | H11: =3131413/1212500 -> 2.5826087
A12: Debt | B12: 3750000 | C12: =B12*C14/B14 -> 0.75566751 | E12: Levered IRR | H12: =IRR(B34:B39) -> 0.29942814
A13: Equity | B13: 1212500 | C13: =B13*C14/B14 -> 0.24433249 | E13: Levered Profit | H13: =2963720-1212500 -> 1751220
A14: Total | B14: =B12+B13 -> 4962500 | C14: 1 | E14: Return on Equity | H14: =H13/1287500 -> 1.3601709
A16: Uses | B16: Total | C16: %
A17: Acquisition | B17: 5000000 | C17: =B17*C20/B20 -> 0.93457944
A18: Loan Fee | B18: 37500 | C18: =B18*C20/B20 -> 0.0070093458
A19: Capital Expenditure | B19: 312500 | C19: =B19*C20/B20 -> 0.058411215
A20: Total | B20: =B17+B18+B19 -> 5350000 | C20: 1
A33: Levered IRR
A34: Year 0 | B34: -1287500
A35: Year 1 | B35: 171156
A36: Year 2 | B36: 189096
A37: Year 3 | B37: 207802
A38: Year 4 | B38: 227306
A39: Year 5 | B39: 3220773

Sheet Monthly Cashflow
A1: Analysis Date | B1: 44197
D2: =B1 -> 44197
D3: 0 | E3: 1 | F3: 2 | G3: 3 | H3: 4 | I3: 5 | J3: 6 | K3: 7 | L3: 8 | M3: 9 | N3: 10 | O3: 11 | P3: 12 | Q3: 13 | R3: 14 | S3: 15 | T3: 16 | U3: 17 | V3: 18 | W3: 19 | X3: 20 | Y3: 21 | Z3: 22 | AA3: 23 | AB3: 24 | AC3: 25 | AD3: 26 | AE3: 27 | AF3: 28 | AG3: 29 | AH3: 30 | AI3: 31 | AJ3: 32 | AK3: 33 | AL3: 34 | AM3: 35 | AN3: 36 | AO3: 37 | AP3: 38 | AQ3: 39 | AR3: 40 | AS3: 41 | AT3: 42 | AU3: 43 | AV3: 44 | AW3: 45 | AX3: 46 | AY3: 47 | AZ3: 48 | BA3: 49 | BB3: 50 | BC3: 51 | BD3: 52 | BE3: 53 | BF3: 54 | BG3: 55 | BH3: 56 | BI3: 57 | BJ3: 58 | BK3: 59 | BL3: 60
A4: Sections required
A5: INCOME
A6: Tenant 1 | B6: Area | E6: 10000 | F6: 10000 | G6: 10000 | H6: 10000 | I6: 10000 | J6: 10000 | K6: 10000 | L6: 10000 | M6: 10000 | N6: 10000 | O6: 10000 | P6: 10000 | Q6: 10000 | R6: 10000 | S6: 10000 | T6: 10000 | U6: 10000 | V6: 10000 | W6: 10000 | X6: 10000 | Y6: 10000 | Z6: 10000 | AA6: 10000 | AB6: 10000 | AC6: 10000 | AD6: 10000 | AE6: 10000 | AF6: 10000 | AG6: 10000 | AH6: 10000 | AI6: 10000 | AJ6: 10000 | AK6: 10000 | AL6: 10000 | AM6: 10000 | AN6: 10000 | AO6: 10000 | AP6: 10000 | AQ6: 10000 | AR6: 10000 | AS6: 10000 | AT6: 10000 | AU6: 10000 | AV6: 10000 | AW6: 10000 | AX6: 10000 | AY6: 10000 | AZ6: 10000 | BA6: 10000 | BB6: 10000 | BC6: 10000 | BD6: 10000 | BE6: 10000 | BF6: 10000 | BG6: 10000 | BH6: 10000 | BI6: 10000 | BJ6: 10000 | BK6: 10000 | BL6: 10000
B7: Annual PSF | D7: 12.15 | E7: =$D$7*(1+0.03) -> 12.5145 | F7: =$D$7*(1+0.03) -> 12.5145 | G7: =$D$7*(1+0.03) -> 12.5145 | H7: =$D$7*(1+0.03) -> 12.5145 | I7: =$D$7*(1+0.03) -> 12.5145 | J7: =$D$7*(1+0.03) -> 12.5145 | K7: =$D$7*(1+0.03) -> 12.5145 | L7: =$D$7*(1+0.03) -> 12.5145 | ... P7: =$D$7*(1+0.03) -> 12.5145 | Q7: =$P$7*(1+0.03) -> 12.889935 | R7: =$P$7*(1+0.03) -> 12.889935 | S7: =$P$7*(1+0.03) -> 12.889935 | T7: =$P$7*(1+0.03) -> 12.889935 | U7: =$P$7*(1+0.03) -> 12.889935 | V7: =$P$7*(1+0.03) -> 12.889935 | W7: =$P$7*(1+0.03) -> 12.889935 | X7: =$P$7*(1+0.03) -> 12.889935 | ... AB7: =$P$7*(1+0.03) -> 12.889935 | AC7: =$AB$7*(1+0.03) -> 13.276633 | AD7: =$AB$7*(1+0.03) -> 13.276633 | AE7: =$AB$7*(1+0.03) -> 13.276633 | AF7: =$AB$7*(1+0.03) -> 13.276633 | AG7: =$AB$7*(1+0.03) -> 13.276633 | AH7: =$AB$7*(1+0.03) -> 13.276633 | AI7: =$AB$7*(1+0.03) -> 13.276633 | AJ7: =$AB$7*(1+0.03) -> 13.276633 | ... AN7: =$AB$7*(1+0.03) -> 13.276633 | AO7: =$AN$7*(1+0.03) -> 13.674932 | AP7: =$AN$7*(1+0.03) -> 13.674932 | AQ7: =$AN$7*(1+0.03) -> 13.674932 | AR7: =$AN$7*(1+0.03) -> 13.674932 | AS7: =$AN$7*(1+0.03) -> 13.674932 | AT7: =$AN$7*(1+0.03) -> 13.674932 | AU7: =$AN$7*(1+0.03) -> 13.674932 | AV7: =$AN$7*(1+0.03) -> 13.674932 | ... AZ7: =$AN$7*(1+0.03) -> 13.674932 | BA7: =$AZ$7*(1+0.03) -> 14.08518 | BB7: =$AZ$7*(1+0.03) -> 14.08518 | BC7: =$AZ$7*(1+0.03) -> 14.08518 | BD7: =$AZ$7*(1+0.03) -> 14.08518 | BE7: =$AZ$7*(1+0.03) -> 14.08518 | BF7: =$AZ$7*(1+0.03) -> 14.08518 | BG7: =$AZ$7*(1+0.03) -> 14.08518 | BH7: =$AZ$7*(1+0.03) -> 14.08518 | ... BL7: =$AZ$7*(1+0.03) -> 14.08518
B8: Monthly Rent | E8: =(E6*E7)/12 -> 10428.75 | F8: =(F6*F7)/12 -> 10428.75 | G8: =(G6*G7)/12 -> 10428.75 | H8: =(H6*H7)/12 -> 10428.75 | I8: =(I6*I7)/12 -> 10428.75 | J8: =(J6*J7)/12 -> 10428.75 | K8: =(K6*K7)/12 -> 10428.75 | L8: =(L6*L7)/12 -> 10428.75 | ... BL8: =(BL6*BL7)/12 -> 11737.65
A9: Tenant 2 | B9: Area | E9: 10000 | F9: 10000 | G9: 10000 | H9: 10000 | I9: 10000 | J9: 10000 | K9: 10000 | L9: 10000 | M9: 10000 | N9: 10000 | O9: 10000 | P9: 10000 | Q9: 10000 | R9: 10000 | S9: 10000 | T9: 10000 | U9: 10000 | V9: 10000 | W9: 10000 | X9: 10000 | Y9: 10000 | Z9: 10000 | AA9: 10000 | AB9: 10000 | AC9: 10000 | AD9: 10000 | AE9: 10000 | AF9: 10000 | AG9: 10000 | AH9: 10000 | AI9: 10000 | AJ9: 10000 | AK9: 10000 | AL9: 10000 | AM9: 10000 | AN9: 10000 | AO9: 10000 | AP9: 10000 | AQ9: 10000 | AR9: 10000 | AS9: 10000 | AT9: 10000 | AU9: 10000 | AV9: 10000 | AW9: 10000 | AX9: 10000 | AY9: 10000 | AZ9: 10000 | BA9: 10000 | BB9: 10000 | BC9: 10000 | BD9: 10000 | BE9: 10000 | BF9: 10000 | BG9: 10000 | BH9: 10000 | BI9: 10000 | BJ9: 10000 | BK9: 10000 | BL9: 10000
B10: Annual PSF | D10: 11.5 | E10: =$D$10*(1+0.03) -> 11.845 | F10: =$D$10*(1+0.03) -> 11.845 | G10: =$D$10*(1+0.03) -> 11.845 | H10: =$D$10*(1+0.03) -> 11.845 | I10: =$D$10*(1+0.03) -> 11.845 | J10: =$D$10*(1+0.03) -> 11.845 | K10: =$D$10*(1+0.03) -> 11.845 | L10: =$D$10*(1+0.03) -> 11.845 | ... P10: =$D$10*(1+0.03) -> 11.845 | Q10: =$P$10*(1+0.03) -> 12.20035 | R10: =$P$10*(1+0.03) -> 12.20035 | S10: =$P$10*(1+0.03) -> 12.20035 | T10: =$P$10*(1+0.03) -> 12.20035 | U10: =$P$10*(1+0.03) -> 12.20035 | V10: =$P$10*(1+0.03) -> 12.20035 | W10: =$P$10*(1+0.03) -> 12.20035 | X10: =$P$10*(1+0.03) -> 12.20035 | ... AB10: =$P$10*(1+0.03) -> 12.20035 | AC10: =$AB$10*(1+0.03) -> 12.566361 | AD10: =$AB$10*(1+0.03) -> 12.566361 | AE10: =$AB$10*(1+0.03) -> 12.566361 | AF10: =$AB$10*(1+0.03) -> 12.566361 | AG10: =$AB$10*(1+0.03) -> 12.566361 | AH10: =$AB$10*(1+0.03) -> 12.566361 | AI10: =$AB$10*(1+0.03) -> 12.566361 | AJ10: =$AB$10*(1+0.03) -> 12.566361 | ... AN10: =$AB$10*(1+0.03) -> 12.566361 | AO10: =$AN$10*(1+0.03) -> 12.943351 | AP10: =$AN$10*(1+0.03) -> 12.943351 | AQ10: =$AN$10*(1+0.03) -> 12.943351 | AR10: =$AN$10*(1+0.03) -> 12.943351 | AS10: =$AN$10*(1+0.03) -> 12.943351 | AT10: =$AN$10*(1+0.03) -> 12.943351 | AU10: =$AN$10*(1+0.03) -> 12.943351 | AV10: =$AN$10*(1+0.03) -> 12.943351 | ... AZ10: =$AN$10*(1+0.03) -> 12.943351 | BA10: =$AZ$10*(1+0.03) -> 13.331652 | BB10: =$AZ$10*(1+0.03) -> 13.331652 | BC10: =$AZ$10*(1+0.03) -> 13.331652 | BD10: =$AZ$10*(1+0.03) -> 13.331652 | BE10: =$AZ$10*(1+0.03) -> 13.331652 | BF10: =$AZ$10*(1+0.03) -> 13.331652 | BG10: =$AZ$10*(1+0.03) -> 13.331652 | BH10: =$AZ$10*(1+0.03) -> 13.331652 | ... BL10: =$AZ$10*(1+0.03) -> 13.331652
B11: Monthly Rent | E11: =(E9*E10)/12 -> 9870.8333 | F11: =(F9*F10)/12 -> 9870.8333 | G11: =(G9*G10)/12 -> 9870.8333 | H11: =(H9*H10)/12 -> 9870.8333 | I11: =(I9*I10)/12 -> 9870.8333 | J11: =(J9*J10)/12 -> 9870.8333 | K11: =(K9*K10)/12 -> 9870.8333 | L11: =(L9*L10)/12 -> 9870.8333 | ... BL11: =(BL9*BL10)/12 -> 11109.71
A12: Tenant 3 | B12: Area | E12: 15000 | F12: 15000 | G12: 15000 | H12: 15000 | I12: 15000 | J12: 15000 | K12: 15000 | L12: 15000 | M12: 15000 | N12: 15000 | O12: 15000 | P12: 15000 | Q12: 15000 | R12: 15000 | S12: 15000 | T12: 15000 | U12: 15000 | V12: 15000 | W12: 15000 | X12: 15000 | Y12: 15000 | Z12: 15000 | AA12: 15000 | AB12: 15000 | AC12: 15000 | AD12: 15000 | AE12: 15000 | AF12: 15000 | AG12: 15000 | AH12: 15000 | AI12: 15000 | AJ12: 15000 | AK12: 15000 | AL12: 15000 | AM12: 15000 | AN12: 15000 | AO12: 15000 | AP12: 15000 | AQ12: 15000 | AR12: 15000 | AS12: 15000 | AT12: 15000 | AU12: 15000 | AV12: 15000 | AW12: 15000 | AX12: 15000 | AY12: 15000 | AZ12: 15000 | BA12: 15000 | BB12: 15000 | BC12: 15000 | BD12: 15000 | BE12: 15000 | BF12: 15000 | BG12: 15000 | BH12: 15000 | BI12: 15000 | BJ12: 15000 | BK12: 15000 | BL12: 15000
B13: Annual PSF | D13: 10.75 | E13: =$D$13*(1+0.03) -> 11.0725 | F13: =$D$13*(1+0.03) -> 11.0725 | G13: =$D$13*(1+0.03) -> 11.0725 | H13: =$D$13*(1+0.03) -> 11.0725 | I13: =$D$13*(1+0.03) -> 11.0725 | J13: =$D$13*(1+0.03) -> 11.0725 | K13: =$D$13*(1+0.03) -> 11.0725 | L13: =$D$13*(1+0.03) -> 11.0725 | ... P13: =$D$13*(1+0.03) -> 11.0725 | Q13: =$P$13*(1+0.03) -> 11.404675 | R13: =$P$13*(1+0.03) -> 11.404675 | S13: =$P$13*(1+0.03) -> 11.404675 | T13: =$P$13*(1+0.03) -> 11.404675 | U13: =$P$13*(1+0.03) -> 11.404675 | V13: =$P$13*(1+0.03) -> 11.404675 | W13: =$P$13*(1+0.03) -> 11.404675 | X13: =$P$13*(1+0.03) -> 11.404675 | ... AB13: =$P$13*(1+0.03) -> 11.404675 | AC13: =$AB$13*(1+0.03) -> 11.746815 | AD13: =$AB$13*(1+0.03) -> 11.746815 | AE13: =$AB$13*(1+0.03) -> 11.746815 | AF13: =$AB$13*(1+0.03) -> 11.746815 | AG13: =$AB$13*(1+0.03) -> 11.746815 | AH13: =$AB$13*(1+0.03) -> 11.746815 | AI13: =$AB$13*(1+0.03) -> 11.746815 | AJ13: =$AB$13*(1+0.03) -> 11.746815 | ... AN13: =$AB$13*(1+0.03) -> 11.746815 | AO13: =$AN$13*(1+0.03) -> 12.09922 | AP13: =$AN$13*(1+0.03) -> 12.09922 | AQ13: =$AN$13*(1+0.03) -> 12.09922 | AR13: =$AN$13*(1+0.03) -> 12.09922 | AS13: =$AN$13*(1+0.03) -> 12.09922 | AT13: =$AN$13*(1+0.03) -> 12.09922 | AU13: =$AN$13*(1+0.03) -> 12.09922 | AV13: =$AN$13*(1+0.03) -> 12.09922 | ... AZ13: =$AN$13*(1+0.03) -> 12.09922 | BA13: =$AZ$13*(1+0.03) -> 12.462196 | BB13: =$AZ$13*(1+0.03) -> 12.462196 | BC13: =$AZ$13*(1+0.03) -> 12.462196 | BD13: =$AZ$13*(1+0.03) -> 12.462196 | BE13: =$AZ$13*(1+0.03) -> 12.462196 | BF13: =$AZ$13*(1+0.03) -> 12.462196 | BG13: =$AZ$13*(1+0.03) -> 12.462196 | BH13: =$AZ$13*(1+0.03) -> 12.462196 | ... BL13: =$AZ$13*(1+0.03) -> 12.462196
B14: Monthly Rent | E14: =(E12*E13)/12 -> 13840.625 | F14: =(F12*F13)/12 -> 13840.625 | G14: =(G12*G13)/12 -> 13840.625 | H14: =(H12*H13)/12 -> 13840.625 | I14: =(I12*I13)/12 -> 13840.625 | J14: =(J12*J13)/12 -> 13840.625 | K14: =(K12*K13)/12 -> 13840.625 | L14: =(L12*L13)/12 -> 13840.625 | ... BL14: =(BL12*BL13)/12 -> 15577.745
A15: Tenant 4 | B15: Area | E15: 5000 | F15: 5000 | G15: 5000 | H15: 5000 | I15: 5000 | J15: 5000 | K15: 5000 | L15: 5000 | M15: 5000 | N15: 5000 | O15: 5000 | P15: 5000 | Q15: 5000 | R15: 5000 | S15: 5000 | T15: 5000 | U15: 5000 | V15: 5000 | W15: 5000 | X15: 5000 | Y15: 5000 | Z15: 5000 | AA15: 5000 | AB15: 5000 | AC15: 5000 | AD15: 5000 | AE15: 5000 | AF15: 5000 | AG15: 5000 | AH15: 5000 | AI15: 5000 | AJ15: 5000 | AK15: 5000 | AL15: 5000 | AM15: 5000 | AN15: 5000 | AO15: 5000 | AP15: 5000 | AQ15: 5000 | AR15: 5000 | AS15: 5000 | AT15: 5000 | AU15: 5000 | AV15: 5000 | AW15: 5000 | AX15: 5000 | AY15: 5000 | AZ15: 5000 | BA15: 5000 | BB15: 5000 | BC15: 5000 | BD15: 5000 | BE15: 5000 | BF15: 5000 | BG15: 5000 | BH15: 5000 | BI15: 5000 | BJ15: 5000 | BK15: 5000 | BL15: 5000
B16: Annual PSF | D16: 12 | E16: =$D$16*(1+0.05) -> 12.6 | F16: =$D$16*(1+0.05) -> 12.6 | G16: =$D$16*(1+0.05) -> 12.6 | H16: =$D$16*(1+0.05) -> 12.6 | I16: =$D$16*(1+0.05) -> 12.6 | J16: =$D$16*(1+0.05) -> 12.6 | K16: =$D$16*(1+0.05) -> 12.6 | L16: =$D$16*(1+0.05) -> 12.6 | ... P16: =$D$16*(1+0.05) -> 12.6 | Q16: =$P$16*(1+0.05) -> 13.23 | R16: =$P$16*(1+0.05) -> 13.23 | S16: =$P$16*(1+0.05) -> 13.23 | T16: =$P$16*(1+0.05) -> 13.23 | U16: =$P$16*(1+0.05) -> 13.23 | V16: =$P$16*(1+0.05) -> 13.23 | W16: =$P$16*(1+0.05) -> 13.23 | X16: =$P$16*(1+0.05) -> 13.23 | ... AB16: =$P$16*(1+0.05) -> 13.23 | AC16: =$AB$16*(1+0.05) -> 13.8915 | AD16: =$AB$16*(1+0.05) -> 13.8915 | AE16: =$AB$16*(1+0.05) -> 13.8915 | AF16: =$AB$16*(1+0.05) -> 13.8915 | AG16: =$AB$16*(1+0.05) -> 13.8915 | AH16: =$AB$16*(1+0.05) -> 13.8915 | AI16: =$AB$16*(1+0.05) -> 13.8915 | AJ16: =$AB$16*(1+0.05) -> 13.8915 | ... AN16: =$AB$16*(1+0.05) -> 13.8915 | AO16: =$AN$16*(1+0.05) -> 14.586075 | AP16: =$AN$16*(1+0.05) -> 14.586075 | AQ16: =$AN$16*(1+0.05) -> 14.586075 | AR16: =$AN$16*(1+0.05) -> 14.586075 | AS16: =$AN$16*(1+0.05) -> 14.586075 | AT16: =$AN$16*(1+0.05) -> 14.586075 | AU16: =$AN$16*(1+0.05) -> 14.586075 | AV16: =$AN$16*(1+0.05) -> 14.586075 | ... AZ16: =$AN$16*(1+0.05) -> 14.586075 | BA16: =$AZ$16*(1+0.05) -> 15.315379 | BB16: =$AZ$16*(1+0.05) -> 15.315379 | BC16: =$AZ$16*(1+0.05) -> 15.315379 | BD16: =$AZ$16*(1+0.05) -> 15.315379 | BE16: =$AZ$16*(1+0.05) -> 15.315379 | BF16: =$AZ$16*(1+0.05) -> 15.315379 | BG16: =$AZ$16*(1+0.05) -> 15.315379 | BH16: =$AZ$16*(1+0.05) -> 15.315379 | ... BL16: =$AZ$16*(1+0.05) -> 15.315379
B17: Monthly Rent | E17: =(E16*E15)/12 -> 5250 | F17: =(F16*F15)/12 -> 5250 | G17: =(G16*G15)/12 -> 5250 | H17: =(H16*H15)/12 -> 5250 | I17: =(I16*I15)/12 -> 5250 | J17: =(J16*J15)/12 -> 5250 | K17: =(K16*K15)/12 -> 5250 | L17: =(L16*L15)/12 -> 5250 | ... BL17: =(BL16*BL15)/12 -> 6381.4078
A18: Tenant 5 | B18: Area | E18: 10000 | F18: 10000 | G18: 10000 | H18: 10000 | I18: 10000 | J18: 10000 | K18: 10000 | L18: 10000 | M18: 10000 | N18: 10000 | O18: 10000 | P18: 10000 | Q18: 10000 | R18: 10000 | S18: 10000 | T18: 10000 | U18: 10000 | V18: 10000 | W18: 10000 | X18: 10000 | Y18: 10000 | Z18: 10000 | AA18: 10000 | AB18: 10000 | AC18: 10000 | AD18: 10000 | AE18: 10000 | AF18: 10000 | AG18: 10000 | AH18: 10000 | AI18: 10000 | AJ18: 10000 | AK18: 10000 | AL18: 10000 | AM18: 10000 | AN18: 10000 | AO18: 10000 | AP18: 10000 | AQ18: 10000 | AR18: 10000 | AS18: 10000 | AT18: 10000 | AU18: 10000 | AV18: 10000 | AW18: 10000 | AX18: 10000 | AY18: 10000 | AZ18: 10000 | BA18: 10000 | BB18: 10000 | BC18: 10000 | BD18: 10000 | BE18: 10000 | BF18: 10000 | BG18: 10000 | BH18: 10000 | BI18: 10000 | BJ18: 10000 | BK18: 10000 | BL18: 10000
B19: Annual PSF | D19: 12 | E19: =E16 -> 12.6 | F19: =F16 -> 12.6 | G19: =G16 -> 12.6 | H19: =H16 -> 12.6 | I19: =I16 -> 12.6 | J19: =J16 -> 12.6 | K19: =K16 -> 12.6 | L19: =L16 -> 12.6 | ... BL19: =BL16 -> 15.315379
B20: Monthly Rent | E20: =( E18*E19)/12 -> 10500 | F20: =( F18*F19)/12 -> 10500 | G20: =( G18*G19)/12 -> 10500 | H20: =( H18*H19)/12 -> 10500 | I20: =( I18*I19)/12 -> 10500 | J20: =( J18*J19)/12 -> 10500 | K20: =( K18*K19)/12 -> 10500 | L20: =( L18*L19)/12 -> 10500 | ... BL20: =( BL18*BL19)/12 -> 12762.816
A21: Tenant 6 | B21: Area | E21: 6000 | F21: 6000 | G21: 6000 | H21: 6000 | I21: 6000 | J21: 6000 | K21: 6000 | L21: 6000 | M21: 6000 | N21: 6000 | O21: 6000 | P21: 6000 | Q21: 6000 | R21: 6000 | S21: 6000 | T21: 6000 | U21: 6000 | V21: 6000 | W21: 6000 | X21: 6000 | Y21: 6000 | Z21: 6000 | AA21: 6000 | AB21: 6000 | AC21: 6000 | AD21: 6000 | AE21: 6000 | AF21: 6000 | AG21: 6000 | AH21: 6000 | AI21: 6000 | AJ21: 6000 | AK21: 6000 | AL21: 6000 | AM21: 6000 | AN21: 6000 | AO21: 6000 | AP21: 6000 | AQ21: 6000 | AR21: 6000 | AS21: 6000 | AT21: 6000 | AU21: 6000 | AV21: 6000 | AW21: 6000 | AX21: 6000 | AY21: 6000 | AZ21: 6000 | BA21: 6000 | BB21: 6000 | BC21: 6000 | BD21: 6000 | BE21: 6000 | BF21: 6000 | BG21: 6000 | BH21: 6000 | BI21: 6000 | BJ21: 6000 | BK21: 6000 | BL21: 6000
B22: Annual PSF | D22: 0 | E22: 0 | F22: 0 | G22: 0 | H22: 0 | I22: 0 | J22: 0 | K22: 0 | L22: 0 | M22: 0 | N22: 0 | O22: 0 | P22: 0 | Q22: 0 | R22: 0 | S22: 0 | T22: 0 | U22: 0 | V22: 0 | W22: 0 | X22: 0 | Y22: 0 | Z22: 0 | AA22: 0 | AB22: 0 | AC22: 0 | AD22: 0 | AE22: 0 | AF22: 0 | AG22: 0 | AH22: 0 | AI22: 0 | AJ22: 0 | AK22: 0 | AL22: 0 | AM22: 0 | AN22: 0 | AO22: 0 | AP22: 0 | AQ22: 0 | AR22: 0 | AS22: 0 | AT22: 0 | AU22: 0 | AV22: 0 | AW22: 0 | AX22: 0 | AY22: 0 | AZ22: 0 | BA22: 0 | BB22: 0 | BC22: 0 | BD22: 0 | BE22: 0 | BF22: 0 | BG22: 0 | BH22: 0 | BI22: 0 | BJ22: 0 | BK22: 0 | BL22: 0
B23: Monthly Rent | E23: =(E21*E22)/12 -> 0 | F23: =(F21*F22)/12 -> 0 | G23: =(G21*G22)/12 -> 0 | H23: =(H21*H22)/12 -> 0 | I23: =(I21*I22)/12 -> 0 | J23: =(J21*J22)/12 -> 0 | K23: =(K21*K22)/12 -> 0 | L23: =(L21*L22)/12 -> 0 | ... BL23: =(BL21*BL22)/12 -> 0
A24: Total Rent | E24: =E8+E11+E14+E17+E20+E23 -> 49890.208 | F24: =F8+F11+F14+F17+F20+F23 -> 49890.208 | G24: =G8+G11+G14+G17+G20+G23 -> 49890.208 | H24: =H8+H11+H14+H17+H20+H23 -> 49890.208 | I24: =I8+I11+I14+I17+I20+I23 -> 49890.208 | J24: =J8+J11+J14+J17+J20+J23 -> 49890.208 | K24: =K8+K11+K14+K17+K20+K23 -> 49890.208 | L24: =L8+L11+L14+L17+L20+L23 -> 49890.208 | ... BL24: =BL8+BL11+BL14+BL17+BL20+BL23 -> 57569.329
A25: Other Incone | E25: 0 | F25: 0 | G25: 0 | H25: 0 | I25: 0 | J25: 0 | K25: 0 | L25: 0 | M25: 0 | N25: 0 | O25: 0 | P25: 0 | Q25: 0 | R25: 0 | S25: 0 | T25: 0 | U25: 0 | V25: 0 | W25: 0 | X25: 0 | Y25: 0 | Z25: 0 | AA25: 0 | AB25: 0 | AC25: 0 | AD25: 0 | AE25: 0 | AF25: 0 | AG25: 0 | AH25: 0 | AI25: 0 | AJ25: 0 | AK25: 0 | AL25: 0 | AM25: 0 | AN25: 0 | AO25: 0 | AP25: 0 | AQ25: 0 | AR25: 0 | AS25: 0 | AT25: 0 | AU25: 0 | AV25: 0 | AW25: 0 | AX25: 0 | AY25: 0 | AZ25: 0 | BA25: 0 | BB25: 0 | BC25: 0 | BD25: 0 | BE25: 0 | BF25: 0 | BG25: 0 | BH25: 0 | BI25: 0 | BJ25: 0 | BK25: 0 | BL25: 0
A26: Vacancy | E26: 0 | F26: 0 | G26: 0 | H26: 0 | I26: 0 | J26: 0 | K26: 0 | L26: 0 | M26: 0 | N26: 0 | O26: 0 | P26: 0 | Q26: 0 | R26: 0 | S26: 0 | T26: 0 | U26: 0 | V26: 0 | W26: 0 | X26: 0 | Y26: 0 | Z26: 0 | AA26: 0 | AB26: 0 | AC26: 0 | AD26: 0 | AE26: 0 | AF26: 0 | AG26: 0 | AH26: 0 | AI26: 0 | AJ26: 0 | AK26: 0 | AL26: 0 | AM26: 0 | AN26: 0 | AO26: 0 | AP26: 0 | AQ26: 0 | AR26: 0 | AS26: 0 | AT26: 0 | AU26: 0 | AV26: 0 | AW26: 0 | AX26: 0 | AY26: 0 | AZ26: 0 | BA26: 0 | BB26: 0 | BC26: 0 | BD26: 0 | BE26: 0 | BF26: 0 | BG26: 0 | BH26: 0 | BI26: 0 | BJ26: 0 | BK26: 0 | BL26: 0
A27: Effective Income | E27: =E24*(1-E26) -> 49890.208 | F27: =F24*(1-F26) -> 49890.208 | G27: =G24*(1-G26) -> 49890.208 | H27: =H24*(1-H26) -> 49890.208 | I27: =I24*(1-I26) -> 49890.208 | J27: =J24*(1-J26) -> 49890.208 | K27: =K24*(1-K26) -> 49890.208 | L27: =L24*(1-L26) -> 49890.208 | ... BL27: =BL24*(1-BL26) -> 57569.329
A28: Total Income | E28: =E25+E27 -> 49890.208 | F28: =F25+F27 -> 49890.208 | G28: =G25+G27 -> 49890.208 | H28: =H25+H27 -> 49890.208 | I28: =I25+I27 -> 49890.208 | J28: =J25+J27 -> 49890.208 | K28: =K25+K27 -> 49890.208 | L28: =L25+L27 -> 49890.208 | ... BL28: =BL25+BL27 -> 57569.329
A30: EXPENSES
A31: CAM | D31: 25000 | E31: =$D$31/12 -> 2083.3333 | F31: =$D$31/12 -> 2083.3333 | G31: =$D$31/12 -> 2083.3333 | H31: =$D$31/12 -> 2083.3333 | I31: =$D$31/12 -> 2083.3333 | J31: =$D$31/12 -> 2083.3333 | K31: =$D$31/12 -> 2083.3333 | L31: =$D$31/12 -> 2083.3333 | ... P31: =$D$31/12 -> 2083.3333 | Q31: =$P$31*(1+0.02) -> 2125 | R31: =$P$31*(1+0.02) -> 2125 | S31: =$P$31*(1+0.02) -> 2125 | T31: =$P$31*(1+0.02) -> 2125 | U31: =$P$31*(1+0.02) -> 2125 | V31: =$P$31*(1+0.02) -> 2125 | W31: =$P$31*(1+0.02) -> 2125 | X31: =$P$31*(1+0.02) -> 2125 | ... AB31: =$P$31*(1+0.02) -> 2125 | AC31: =$AB$31*(1+0.02) -> 2167.5 | AD31: =$AB$31*(1+0.02) -> 2167.5 | AE31: =$AB$31*(1+0.02) -> 2167.5 | AF31: =$AB$31*(1+0.02) -> 2167.5 | AG31: =$AB$31*(1+0.02) -> 2167.5 | AH31: =$AB$31*(1+0.02) -> 2167.5 | AI31: =$AB$31*(1+0.02) -> 2167.5 | AJ31: =$AB$31*(1+0.02) -> 2167.5 | ... AN31: =$AB$31*(1+0.02) -> 2167.5 | AO31: =$AN$31*(1+0.02) -> 2210.85 | AP31: =$AN$31*(1+0.02) -> 2210.85 | AQ31: =$AN$31*(1+0.02) -> 2210.85 | AR31: =$AN$31*(1+0.02) -> 2210.85 | AS31: =$AN$31*(1+0.02) -> 2210.85 | AT31: =$AN$31*(1+0.02) -> 2210.85 | AU31: =$AN$31*(1+0.02) -> 2210.85 | AV31: =$AN$31*(1+0.02) -> 2210.85 | ... AZ31: =$AN$31*(1+0.02) -> 2210.85 | BA31: =$AZ$31*(1+0.02) -> 2255.067 | BB31: =$AZ$31*(1+0.02) -> 2255.067 | BC31: =$AZ$31*(1+0.02) -> 2255.067 | BD31: =$AZ$31*(1+0.02) -> 2255.067 | BE31: =$AZ$31*(1+0.02) -> 2255.067 | BF31: =$AZ$31*(1+0.02) -> 2255.067 | BG31: =$AZ$31*(1+0.02) -> 2255.067 | BH31: =$AZ$31*(1+0.02) -> 2255.067 | ... BL31: =$AZ$31*(1+0.02) -> 2255.067
A32: Taxes | D32: 75000 | E32: =$D$32/12 -> 6250 | F32: =$D$32/12 -> 6250 | G32: =$D$32/12 -> 6250 | H32: =$D$32/12 -> 6250 | I32: =$D$32/12 -> 6250 | J32: =$D$32/12 -> 6250 | K32: =$D$32/12 -> 6250 | L32: =$D$32/12 -> 6250 | ... P32: =$D$32/12 -> 6250 | Q32: =$P$32*(1+0.02) -> 6375 | R32: =$P$32*(1+0.02) -> 6375 | S32: =$P$32*(1+0.02) -> 6375 | T32: =$P$32*(1+0.02) -> 6375 | U32: =$P$32*(1+0.02) -> 6375 | V32: =$P$32*(1+0.02) -> 6375 | W32: =$P$32*(1+0.02) -> 6375 | X32: =$P$32*(1+0.02) -> 6375 | ... AB32: =$P$32*(1+0.02) -> 6375 | AC32: =$AB$32*(1+0.02) -> 6502.5 | AD32: =$AB$32*(1+0.02) -> 6502.5 | AE32: =$AB$32*(1+0.02) -> 6502.5 | AF32: =$AB$32*(1+0.02) -> 6502.5 | AG32: =$AB$32*(1+0.02) -> 6502.5 | AH32: =$AB$32*(1+0.02) -> 6502.5 | AI32: =$AB$32*(1+0.02) -> 6502.5 | AJ32: =$AB$32*(1+0.02) -> 6502.5 | ... AN32: =$AB$32*(1+0.02) -> 6502.5 | AO32: =$AN$32*(1+0.02) -> 6632.55 | AP32: =$AN$32*(1+0.02) -> 6632.55 | AQ32: =$AN$32*(1+0.02) -> 6632.55 | AR32: =$AN$32*(1+0.02) -> 6632.55 | AS32: =$AN$32*(1+0.02) -> 6632.55 | AT32: =$AN$32*(1+0.02) -> 6632.55 | AU32: =$AN$32*(1+0.02) -> 6632.55 | AV32: =$AN$32*(1+0.02) -> 6632.55 | ... AZ32: =$AN$32*(1+0.02) -> 6632.55 | BA32: =$AZ$32*(1+0.02) -> 6765.201 | BB32: =$AZ$32*(1+0.02) -> 6765.201 | BC32: =$AZ$32*(1+0.02) -> 6765.201 | BD32: =$AZ$32*(1+0.02) -> 6765.201 | BE32: =$AZ$32*(1+0.02) -> 6765.201 | BF32: =$AZ$32*(1+0.02) -> 6765.201 | BG32: =$AZ$32*(1+0.02) -> 6765.201 | BH32: =$AZ$32*(1+0.02) -> 6765.201 | ... BL32: =$AZ$32*(1+0.02) -> 6765.201
A33: Insurance | D33: 25000 | E33: =$D$33/12 -> 2083.3333 | F33: =$D$33/12 -> 2083.3333 | G33: =$D$33/12 -> 2083.3333 | H33: =$D$33/12 -> 2083.3333 | I33: =$D$33/12 -> 2083.3333 | J33: =$D$33/12 -> 2083.3333 | K33: =$D$33/12 -> 2083.3333 | L33: =$D$33/12 -> 2083.3333 | ... P33: =$D$33/12 -> 2083.3333 | Q33: =$P$33*(1+0.02) -> 2125 | R33: =$P$33*(1+0.02) -> 2125 | S33: =$P$33*(1+0.02) -> 2125 | T33: =$P$33*(1+0.02) -> 2125 | U33: =$P$33*(1+0.02) -> 2125 | V33: =$P$33*(1+0.02) -> 2125 | W33: =$P$33*(1+0.02) -> 2125 | X33: =$P$33*(1+0.02) -> 2125 | ... AB33: =$P$33*(1+0.02) -> 2125 | AC33: =$AB$33*(1+0.02) -> 2167.5 | AD33: =$AB$33*(1+0.02) -> 2167.5 | AE33: =$AB$33*(1+0.02) -> 2167.5 | AF33: =$AB$33*(1+0.02) -> 2167.5 | AG33: =$AB$33*(1+0.02) -> 2167.5 | AH33: =$AB$33*(1+0.02) -> 2167.5 | AI33: =$AB$33*(1+0.02) -> 2167.5 | AJ33: =$AB$33*(1+0.02) -> 2167.5 | ... AN33: =$AB$33*(1+0.02) -> 2167.5 | AO33: =$AN$33*(1+0.02) -> 2210.85 | AP33: =$AN$33*(1+0.02) -> 2210.85 | AQ33: =$AN$33*(1+0.02) -> 2210.85 | AR33: =$AN$33*(1+0.02) -> 2210.85 | AS33: =$AN$33*(1+0.02) -> 2210.85 | AT33: =$AN$33*(1+0.02) -> 2210.85 | AU33: =$AN$33*(1+0.02) -> 2210.85 | AV33: =$AN$33*(1+0.02) -> 2210.85 | ... AZ33: =$AN$33*(1+0.02) -> 2210.85 | BA33: =$AZ$33*(1+0.02) -> 2255.067 | BB33: =$AZ$33*(1+0.02) -> 2255.067 | BC33: =$AZ$33*(1+0.02) -> 2255.067 | BD33: =$AZ$33*(1+0.02) -> 2255.067 | BE33: =$AZ$33*(1+0.02) -> 2255.067 | BF33: =$AZ$33*(1+0.02) -> 2255.067 | BG33: =$AZ$33*(1+0.02) -> 2255.067 | BH33: =$AZ$33*(1+0.02) -> 2255.067 | ... BL33: =$AZ$33*(1+0.02) -> 2255.067
A34: Utilities | D34: 20000 | E34: =$D$34/12 -> 1666.6667 | F34: =$D$34/12 -> 1666.6667 | G34: =$D$34/12 -> 1666.6667 | H34: =$D$34/12 -> 1666.6667 | I34: =$D$34/12 -> 1666.6667 | J34: =$D$34/12 -> 1666.6667 | K34: =$D$34/12 -> 1666.6667 | L34: =$D$34/12 -> 1666.6667 | ... P34: =$D$34/12 -> 1666.6667 | Q34: =$P$34*(1+0.02) -> 1700 | R34: =$P$34*(1+0.02) -> 1700 | S34: =$P$34*(1+0.02) -> 1700 | T34: =$P$34*(1+0.02) -> 1700 | U34: =$P$34*(1+0.02) -> 1700 | V34: =$P$34*(1+0.02) -> 1700 | W34: =$P$34*(1+0.02) -> 1700 | X34: =$P$34*(1+0.02) -> 1700 | ... AB34: =$P$34*(1+0.02) -> 1700 | AC34: =$AB$34*(1+0.02) -> 1734 | AD34: =$AB$34*(1+0.02) -> 1734 | AE34: =$AB$34*(1+0.02) -> 1734 | AF34: =$AB$34*(1+0.02) -> 1734 | AG34: =$AB$34*(1+0.02) -> 1734 | AH34: =$AB$34*(1+0.02) -> 1734 | AI34: =$AB$34*(1+0.02) -> 1734 | AJ34: =$AB$34*(1+0.02) -> 1734 | ... AN34: =$AB$34*(1+0.02) -> 1734 | AO34: =$AN$34*(1+0.02) -> 1768.68 | AP34: =$AN$34*(1+0.02) -> 1768.68 | AQ34: =$AN$34*(1+0.02) -> 1768.68 | AR34: =$AN$34*(1+0.02) -> 1768.68 | AS34: =$AN$34*(1+0.02) -> 1768.68 | AT34: =$AN$34*(1+0.02) -> 1768.68 | AU34: =$AN$34*(1+0.02) -> 1768.68 | AV34: =$AN$34*(1+0.02) -> 1768.68 | ... AZ34: =$AN$34*(1+0.02) -> 1768.68 | BA34: =$AZ$34*(1+0.02) -> 1804.0536 | BB34: =$AZ$34*(1+0.02) -> 1804.0536 | BC34: =$AZ$34*(1+0.02) -> 1804.0536 | BD34: =$AZ$34*(1+0.02) -> 1804.0536 | BE34: =$AZ$34*(1+0.02) -> 1804.0536 | BF34: =$AZ$34*(1+0.02) -> 1804.0536 | BG34: =$AZ$34*(1+0.02) -> 1804.0536 | BH34: =$AZ$34*(1+0.02) -> 1804.0536 | ... BL34: =$AZ$34*(1+0.02) -> 1804.0536
A35: Repairs | D35: 45000 | E35: =$D$35/12 -> 3750 | F35: =$D$35/12 -> 3750 | G35: =$D$35/12 -> 3750 | H35: =$D$35/12 -> 3750 | I35: =$D$35/12 -> 3750 | J35: =$D$35/12 -> 3750 | K35: =$D$35/12 -> 3750 | L35: =$D$35/12 -> 3750 | ... P35: =$D$35/12 -> 3750 | Q35: =$P$35*(1+0.02) -> 3825 | R35: =$P$35*(1+0.02) -> 3825 | S35: =$P$35*(1+0.02) -> 3825 | T35: =$P$35*(1+0.02) -> 3825 | U35: =$P$35*(1+0.02) -> 3825 | V35: =$P$35*(1+0.02) -> 3825 | W35: =$P$35*(1+0.02) -> 3825 | X35: =$P$35*(1+0.02) -> 3825 | ... AB35: =$P$35*(1+0.02) -> 3825 | AC35: =$AB$35*(1+0.02) -> 3901.5 | AD35: =$AB$35*(1+0.02) -> 3901.5 | AE35: =$AB$35*(1+0.02) -> 3901.5 | AF35: =$AB$35*(1+0.02) -> 3901.5 | AG35: =$AB$35*(1+0.02) -> 3901.5 | AH35: =$AB$35*(1+0.02) -> 3901.5 | AI35: =$AB$35*(1+0.02) -> 3901.5 | AJ35: =$AB$35*(1+0.02) -> 3901.5 | ... AN35: =$AB$35*(1+0.02) -> 3901.5 | AO35: =$AN$35*(1+0.02) -> 3979.53 | AP35: =$AN$35*(1+0.02) -> 3979.53 | AQ35: =$AN$35*(1+0.02) -> 3979.53 | AR35: =$AN$35*(1+0.02) -> 3979.53 | AS35: =$AN$35*(1+0.02) -> 3979.53 | AT35: =$AN$35*(1+0.02) -> 3979.53 | AU35: =$AN$35*(1+0.02) -> 3979.53 | AV35: =$AN$35*(1+0.02) -> 3979.53 | ... AZ35: =$AN$35*(1+0.02) -> 3979.53 | BA35: =$AZ$35*(1+0.02) -> 4059.1206 | BB35: =$AZ$35*(1+0.02) -> 4059.1206 | BC35: =$AZ$35*(1+0.02) -> 4059.1206 | BD35: =$AZ$35*(1+0.02) -> 4059.1206 | BE35: =$AZ$35*(1+0.02) -> 4059.1206 | BF35: =$AZ$35*(1+0.02) -> 4059.1206 | BG35: =$AZ$35*(1+0.02) -> 4059.1206 | BH35: =$AZ$35*(1+0.02) -> 4059.1206 | ... BL35: =$AZ$35*(1+0.02) -> 4059.1206
A36: Total Expenses | E36: =E31+E32+E33+E34+E35 -> 15833.333 | F36: =F31+F32+F33+F34+F35 -> 15833.333 | G36: =G31+G32+G33+G34+G35 -> 15833.333 | H36: =H31+H32+H33+H34+H35 -> 15833.333 | I36: =I31+I32+I33+I34+I35 -> 15833.333 | J36: =J31+J32+J33+J34+J35 -> 15833.333 | K36: =K31+K32+K33+K34+K35 -> 15833.333 | L36: =L31+L32+L33+L34+L35 -> 15833.333 | ... BL36: =BL31+BL32+BL33+BL34+BL35 -> 17138.509
A38: NOI | E38: =E28-E36 -> 34056.875 | F38: =F28-F36 -> 34056.875 | G38: =G28-G36 -> 34056.875 | H38: =H28-H36 -> 34056.875 | I38: =I28-I36 -> 34056.875 | J38: =J28-J36 -> 34056.875 | K38: =K28-K36 -> 34056.875 | L38: =L28-L36 -> 34056.875 | ... BL38: =BL28-BL36 -> 40430.819
A40: Cast Flow Before Debt | E40: =E38 -> 34056.875 | F40: =F38 -> 34056.875 | G40: =G38 -> 34056.875 | H40: =H38 -> 34056.875 | I40: =I38 -> 34056.875 | J40: =J38 -> 34056.875 | K40: =K38 -> 34056.875 | L40: =L38 -> 34056.875 | ... BL40: =BL38 -> 40430.819
A42: Interest | E42: =INDIRECT("Amortization!D" & (COLUMN()-3)) -> 12500 | F42: =INDIRECT("Amortization!D" & (COLUMN()-3)) -> 12475.687 | G42: =INDIRECT("Amortization!D" & (COLUMN()-3)) -> 12451.293 | H42: =INDIRECT("Amortization!D" & (COLUMN()-3)) -> 12426.818 | I42: =INDIRECT("Amortization!D" & (COLUMN()-3)) -> 12402.261 | J42: =INDIRECT("Amortization!D" & (COLUMN()-3)) -> 12377.622 | K42: =INDIRECT("Amortization!D" & (COLUMN()-3)) -> 12352.901 | L42: =INDIRECT("Amortization!D" & (COLUMN()-3)) -> 12328.098 | ... BL42: =INDIRECT("Amortization!D" & (COLUMN()-3)) -> 10917.664
A43: Principal | E43: =INDIRECT("Amortization!e" & (COLUMN()-3)) -> 7293.8815 | F43: =INDIRECT("Amortization!e" & (COLUMN()-3)) -> 7318.1944 | G43: =INDIRECT("Amortization!e" & (COLUMN()-3)) -> 7342.5884 | H43: =INDIRECT("Amortization!e" & (COLUMN()-3)) -> 7367.0637 | I43: =INDIRECT("Amortization!e" & (COLUMN()-3)) -> 7391.6206 | J43: =INDIRECT("Amortization!e" & (COLUMN()-3)) -> 7416.2593 | K43: =INDIRECT("Amortization!e" & (COLUMN()-3)) -> 7440.9802 | L43: =INDIRECT("Amortization!e" & (COLUMN()-3)) -> 7465.7835 | ... BL43: =INDIRECT("Amortization!e" & (COLUMN()-3)) -> 8876.2171
A44: Debt Service | E44: =E42+E43 -> 19793.882 | F44: =F42+F43 -> 19793.882 | G44: =G42+G43 -> 19793.882 | H44: =H42+H43 -> 19793.882 | I44: =I42+I43 -> 19793.882 | J44: =J42+J43 -> 19793.882 | K44: =K42+K43 -> 19793.882 | L44: =L42+L43 -> 19793.882 | ... BL44: =BL42+BL43 -> 19793.882
...

Sheet Yearly Cashflow
A2: * Summarize the monthly Cash flow Annually here
C4: 0 | D4: 1 | E4: 2 | F4: 3 | G4: 4 | H4: 5
A5: Cash Flow After Debt | D5: =SUM('Monthly Cashflow'!E46:'Monthly Cashflow'!P46) -> 171155.92 | E5: =SUM('Monthly Cashflow'!Q46:'Monthly Cashflow'!AB46) -> 189096.4 | F5: =SUM('Monthly Cashflow'!AC46:'Monthly Cashflow'!AN46) -> 207802.09 | G5: =SUM('Monthly Cashflow'!AO46:'Monthly Cashflow'!AZ46) -> 227306.16 | H5: =SUM('Monthly Cashflow'!BA46:'Monthly Cashflow'!BL46) -> 247643.26
A6: Year 0 equity | C6: -1287500
A7: NOI (Year 5) | H7: =SUM('Monthly Cashflow'!BA38:'Monthly Cashflow'!BL38) -> 485169.83
A8: Terminal Sale Price | H8: =H7/0.075 -> 6468931.1
A9: Selling Costs 2% | H9: =H8*-0.02 -> -129378.62
A10: Net Sale Proceeds | H10: =H8+H9-H11 -> 3073129.4
A11: Loan Payoff | H11: =Amortization!F61 -> 3266423.1
A13: Final year 5 Cash Flow | H13: =H5+H10 -> 3320772.6

Sheet Amortization
A1: Months | B1: Opening Balance | C1: Monthly Payment | D1: Interest | E1: Principal | F1: Closing Balance
A2: 1 | B2: 3750000 | C2: =PMT(4%/12,300,-3750000) -> 19793.882 | D2: =B2*4%/12 -> 12500 | E2: =C2-D2 -> 7293.8815 | F2: =B2-E2 -> 3742706.1
A3: 2 | B3: =F2 -> 3742706.1 | C3: =PMT(4%/12,300,-3750000) -> 19793.882 | D3: =B3*4%/12 -> 12475.687 | E3: =C3-D3 -> 7318.1944 | F3: =B3-E3 -> 3735387.9 | H3: Amortization of Loan
A4: 3 | B4: =F3 -> 3735387.9 | C4: =PMT(4%/12,300,-3750000) -> 19793.882 | D4: =B4*4%/12 -> 12451.293 | E4: =C4-D4 -> 7342.5884 | F4: =B4-E4 -> 3728045.3
A5: 4 | B5: =F4 -> 3728045.3 | C5: =PMT(4%/12,300,-3750000) -> 19793.882 | D5: =B5*4%/12 -> 12426.818 | E5: =C5-D5 -> 7367.0637 | F5: =B5-E5 -> 3720678.3
A6: 5 | B6: =F5 -> 3720678.3 | C6: =PMT(4%/12,300,-3750000) -> 19793.882 | D6: =B6*4%/12 -> 12402.261 | E6: =C6-D6 -> 7391.6206 | F6: =B6-E6 -> 3713286.7
A7: 6 | B7: =F6 -> 3713286.7 | C7: =PMT(4%/12,300,-3750000) -> 19793.882 | D7: =B7*4%/12 -> 12377.622 | E7: =C7-D7 -> 7416.2593 | F7: =B7-E7 -> 3705870.4
A8: 7 | B8: =F7 -> 3705870.4 | C8: =PMT(4%/12,300,-3750000) -> 19793.882 | D8: =B8*4%/12 -> 12352.901 | E8: =C8-D8 -> 7440.9802 | F8: =B8-E8 -> 3698429.4
A9: 8 | B9: =F8 -> 3698429.4 | C9: =PMT(4%/12,300,-3750000) -> 19793.882 | D9: =B9*4%/12 -> 12328.098 | E9: =C9-D9 -> 7465.7835 | F9: =B9-E9 -> 3690963.6
A10: 9 | B10: =F9 -> 3690963.6 | C10: =PMT(4%/12,300,-3750000) -> 19793.882 | D10: =B10*4%/12 -> 12303.212 | E10: =C10-D10 -> 7490.6694 | F10: =B10-E10 -> 3683473
A11: 10 | B11: =F10 -> 3683473 | C11: =PMT(4%/12,300,-3750000) -> 19793.882 | D11: =B11*4%/12 -> 12278.243 | E11: =C11-D11 -> 7515.6383 | F11: =B11-E11 -> 3675957.3
A12: 11 | B12: =F11 -> 3675957.3 | C12: =PMT(4%/12,300,-3750000) -> 19793.882 | D12: =B12*4%/12 -> 12253.191 | E12: =C12-D12 -> 7540.6904 | F12: =B12-E12 -> 3668416.6
A13: 12 | B13: =F12 -> 3668416.6 | C13: =PMT(4%/12,300,-3750000) -> 19793.882 | D13: =B13*4%/12 -> 12228.055 | E13: =C13-D13 -> 7565.8261 | F13: =B13-E13 -> 3660850.8
A14: 13 | B14: =F13 -> 3660850.8 | C14: =PMT(4%/12,300,-3750000) -> 19793.882 | D14: =B14*4%/12 -> 12202.836 | E14: =C14-D14 -> 7591.0455 | F14: =B14-E14 -> 3653259.8
A15: 14 | B15: =F14 -> 3653259.8 | C15: =PMT(4%/12,300,-3750000) -> 19793.882 | D15: =B15*4%/12 -> 12177.533 | E15: =C15-D15 -> 7616.349 | F15: =B15-E15 -> 3645643.4
... A25: 24 | B25: =F24 -> 3575943.6 | C25: =PMT(4%/12,300,-3750000) -> 19793.882 | D25: =B25*4%/12 -> 11919.812 | E25: =C25-D25 -> 7874.0695 | F25: =B25-E25 -> 3568069.5
A26: 25 | B26: =F25 -> 3568069.5 | C26: =PMT(4%/12,300,-3750000) -> 19793.882 | D26: =B26*0.04/12 -> 11893.565 | E26: =C26-D26 -> 7900.3164 | F26: =B26-E26 -> 3560169.2
A27: 26 | B27: =F26 -> 3560169.2 | C27: =PMT(4%/12,300,-3750000) -> 19793.882 | D27: =B27*4%/12 -> 11867.231 | E27: =C27-D27 -> 7926.6508 | F27: =B27-E27 -> 3552242.6
A28: 27 | B28: =F27 -> 3552242.6 | C28: =PMT(4%/12,300,-3750000) -> 19793.882 | D28: =B28*4%/12 -> 11840.809 | E28: =C28-D28 -> 7953.073 | F28: =B28-E28 -> 3544289.5
A29: 28 | B29: =F28 -> 3544289.5 | C29: =PMT(4%/12,300,-3750000) -> 19793.882 | D29: =B29*4%/12 -> 11814.298 | E29: =C29-D29 -> 7979.5832 | F29: =B29-E29 -> 3536309.9
A30: 29 | B30: =F29 -> 3536309.9 | C30: =PMT(4%/12,300,-3750000) -> 19793.882 | D30: =B30*4%/12 -> 11787.7 | E30: =C30-D30 -> 8006.1818 | F30: =B30-E30 -> 3528303.7
A31: 30 | B31: =F30 -> 3528303.7 | C31: =PMT(4%/12,300,-3750000) -> 19793.882 | D31: =B31*4%/12 -> 11761.012 | E31: =C31-D31 -> 8032.8691 | F31: =B31-E31 -> 3520270.9
A32: 31 | B32: =F31 -> 3520270.9 | C32: =PMT(4%/12,300,-3750000) -> 19793.882 | D32: =B32*4%/12 -> 11734.236 | E32: =C32-D32 -> 8059.6453 | F32: =B32-E32 -> 3512211.2
A33: 32 | B33: =F32 -> 3512211.2 | C33: =PMT(4%/12,300,-3750000) -> 19793.882 | D33: =B33*4%/12 -> 11707.371 | E33: =C33-D33 -> 8086.5108 | F33: =B33-E33 -> 3504124.7
A34: 33 | B34: =F33 -> 3504124.7 | C34: =PMT(4%/12,300,-3750000) -> 19793.882 | D34: =B34*4%/12 -> 11680.416 | E34: =C34-D34 -> 8113.4658 | F34: =B34-E34 -> 3496011.2
A35: 34 | B35: =F34 -> 3496011.2 | C35: =PMT(4%/12,300,-3750000) -> 19793.882 | D35: =B35*4%/12 -> 11653.371 | E35: =C35-D35 -> 8140.5107 | F35: =B35-E35 -> 3487870.7
A36: 35 | B36: =F35 -> 3487870.7 | C36: =PMT(4%/12,300,-3750000) -> 19793.882 | D36: =B36*4%/12 -> 11626.236 | E36: =C36-D36 -> 8167.6458 | F36: =B36-E36 -> 3479703.1
A37: 36 | B37: =F36 -> 3479703.1 | C37: =PMT(4%/12,300,-3750000) -> 19793.882 | D37: =B37*4%/12 -> 11599.01 | E37: =C37-D37 -> 8194.8712 | F37: =B37-E37 -> 3471508.2
A38: 37 | B38: =F37 -> 3471508.2 | C38: =PMT(4%/12,300,-3750000) -> 19793.882 | D38: =B38*4%/12 -> 11571.694 | E38: =C38-D38 -> 8222.1875 | F38: =B38-E38 -> 3463286
... A61: 60 | B61: =F60 -> 3275299.3 | C61: =PMT(4%/12,300,-3750000) -> 19793.882 | D61: =B61*4%/12 -> 10917.664 | E61: =C61-D61 -> 8876.2171 | F61: =B61-E61 -> 3266423.1
A62: Total | C62: =SUM(C2:C61) -> 1187632.9 | E62: =SUM(E2:E61) -> 483576.89
